<?xml version="1.0" encoding="utf-8"?>
<!-- This URDF was automatically created by SolidWorks to URDF Exporter! Originally created by Stephen Brawner (brawner@gmail.com) 
     Commit Version: 1.6.0-4-g7f85cfe  Build Version: 1.6.7995.38578
     For more information, please see http://wiki.ros.org/sw_urdf_exporter -->
<robot name="boe_bot">
  <!-- Add base_footprint as the root link to avoid KDL inertia warning -->
  <link name="base_footprint"/>
  <!-- Connect base_footprint to base_link -->
  <joint name="base_footprint_to_base_link" type="fixed">
    <parent link="base_footprint"/>
    <child link="base_link"/>
    <origin xyz="0 0 0.015" rpy="0 0 0"/> <!-- Adjust z to bring base_footprint to ground level -->
  </joint>

  <link name="base_link">
    <inertial>
      <origin xyz="0.015372613233287 -3.46944695195361E-17 -0.0112885052624893" rpy="0 0 0"/>
      <mass value="0.0845069146251862"/>
      <inertia ixx="2.81611735996107E-05" ixy="2.16913313552812E-20" ixz="1.05758867413716E-06"
               iyy="4.27824591768325E-05" iyz="-4.86011791909739E-22" izz="6.37632690827645E-05"/>
    </inertial>
    <visual>
      <origin xyz="0 0 0" rpy="0 0 0"/>
      <geometry>
        <mesh filename="package://omni_diff/meshes/boe_bot/base_link.STL"/>
      </geometry>
      <material name="">
        <color rgba="0.796078431372549 0.823529411764706 0.937254901960784 1"/>
      </material>
    </visual>
    <collision>
      <origin xyz="0 0 0" rpy="0 0 0"/>
      <geometry>
        <mesh filename="package://omni_diff/meshes/boe_bot/base_link.STL"/>
      </geometry>
    </collision>
  </link>

  <link name="wheel_left_link">
    <inertial>
      <origin xyz="0 0.00553796497701515 -3.79470760369927E-18" rpy="0 0 0"/>
      <mass value="0.2130642793486274"/>
      <inertia ixx="4.32893090293568E-06" ixy="5.41845433689761E-23" ixz="1.73123420637818E-13"
               iyy="8.57657172030877E-06" iyz="-4.8491845912464E-22" izz="4.32893075375732E-06"/>
    </inertial>
    <visual>
      <origin xyz="0 0 0" rpy="0 0 0"/>
      <geometry>
        <mesh filename="package://omni_diff/meshes/boe_bot/wheel_left_link.STL"/>
      </geometry>
      <material name="">
        <color rgba="0.796078431372549 0.823529411764706 0.937254901960784 1"/>
      </material>
    </visual>
    <collision>
      <origin xyz="0 0 0" rpy="0 0 0"/>
      <geometry>
        <mesh filename="package://omni_diff/meshes/boe_bot/wheel_left_link.STL"/>
      </geometry>
    </collision>
  </link>

  <joint name="wheel_left_joint" type="continuous">
    <origin xyz="0.0335770220595312 0.0505 -0.0150000000000002" rpy="0 0 0"/>
    <parent link="base_link"/>
    <child link="wheel_left_link"/>
    <axis xyz="0 1 0"/>
  </joint>

  <link name="wheel_right_link">
    <inertial>
      <origin xyz="0 -0.00553796497701514 1.07336015076065E-17" rpy="0 0 0"/>
      <mass value="0.2130642793486274"/>
      <inertia ixx="4.32893100565209E-06" ixy="3.64755459763141E-22" ixz="6.40155716027221E-14"
               iyy="8.57657172030879E-06" iyz="-1.46386124150942E-20" izz="4.32893065104093E-06"/>
    </inertial>
    <visual>
      <origin xyz="0 0 0" rpy="0 0 0"/>
      <geometry>
        <mesh filename="package://omni_diff/meshes/boe_bot/wheel_right_link.STL"/>
      </geometry>
      <material name="">
        <color rgba="0.796078431372549 0.823529411764706 0.937254901960784 1"/>
      </material>
    </visual>
    <collision>
      <origin xyz="0 0 0" rpy="0 0 0"/>
      <geometry>
        <mesh filename="package://omni_diff/meshes/boe_bot/wheel_right_link.STL"/>
      </geometry>
    </collision>
  </link>

  <joint name="wheel_right_joint" type="continuous">
    <origin xyz="0.0335770220595312 -0.0505000000000001 -0.015" rpy="0 0 0"/>
    <parent link="base_link"/>
    <child link="wheel_right_link"/>
    <axis xyz="0 1 0"/>
  </joint>

  <link name="base_caster_link">
    <inertial>
      <origin xyz="-0.0104678852334143 1.57497942465668E-07 -0.0071134358279898" rpy="0 0 0"/>
      <mass value="0.10124862338167261"/>
      <inertia ixx="1.83848997721061E-07" ixy="-1.93002189856831E-11" ixz="-2.25796263159261E-08"
               iyy="2.78831217705956E-07" iyz="-1.1602793994816E-11" izz="2.85184016425339E-07"/>
    </inertial>
    <visual>
      <origin xyz="0 0 0" rpy="0 0 0"/>
      <geometry>
        <mesh filename="package://omni_diff/meshes/boe_bot/base_caster_link.STL"/>
      </geometry>
      <material name="">
        <color rgba="0.792156862745098 0.819607843137255 0.933333333333333 1"/>
      </material>
    </visual>
    <collision>
      <origin xyz="0 0 0" rpy="0 0 0"/>
      <geometry>
        <mesh filename="package://omni_diff/meshes/boe_bot/base_caster_link.STL"/>
      </geometry>
    </collision>
  </link>

  <joint name="base_caster_joint" type="continuous">
    <origin xyz="-0.0385214248009794 0 -0.00719409656050521" rpy="0 0 0"/>
    <parent link="base_link"/>
    <child link="base_caster_link"/>
    <axis xyz="0 0 1"/>
  </joint>

  <link name="wheel_caster_link">
    <inertial>
      <origin xyz="0 -0.00742574845928592 -1.73472347597681E-18" rpy="0 0 0"/>
      <mass value="0.10767892497936741"/>
      <inertia ixx="8.07278072682819E-07" ixy="5.64490306617491E-23" ixz="1.54955240768055E-22"
               iyy="1.39986458533007E-06" iyz="-8.48543971596133E-24" izz="8.07278072682819E-07"/>
    </inertial>
    <visual>
      <origin xyz="0 0 0" rpy="0 0 0"/>
      <geometry>
        <mesh filename="package://omni_diff/meshes/boe_bot/wheel_caster_link.STL"/>
      </geometry>
      <material name="">
        <color rgba="0.792156862745098 0.819607843137255 0.933333333333333 1"/>
      </material>
    </visual>
    <collision>
      <origin xyz="0 0 0" rpy="0 0 0"/>
      <geometry>
        <mesh filename="package://omni_diff/meshes/boe_bot/wheel_caster_link.STL"/>
      </geometry>
    </collision>
  </link>

  <joint name="wheel_caster_joint" type="continuous">
    <origin xyz="-0.0184 0.00740252051557694 -0.02346" rpy="0 0 0"/>
    <parent link="base_caster_link"/>
    <child link="wheel_caster_link"/>
    <axis xyz="0 1 0"/>
  </joint>

  <link name="lidar_link">
    <inertial>
      <origin xyz="-0.000563485694278578 -4.9454389998746E-05 -0.0270014519405859" rpy="0 0 0"/>
      <mass value="0.065382751635991"/>
      <inertia ixx="7.88455572217802E-05" ixy="2.72193273405131E-07" ixz="2.17895059451145E-06"
               iyy="7.52099178826257E-05" iyz="1.62277412641598E-07" izz="0.000109946753058707"/>
    </inertial>
    <visual>
      <origin xyz="0 0 0" rpy="0 0 0"/>
      <geometry>
        <mesh filename="package://omni_diff/meshes/boe_bot/lidar_link.STL"/>
      </geometry>
      <material name="">
        <color rgba="0.752941176470588 0.752941176470588 0.752941176470588 0.4"/>
      </material>
    </visual>
    <collision>
      <origin xyz="0 0 0" rpy="0 0 0"/>
      <geometry>
        <mesh filename="package://omni_diff/meshes/boe_bot/lidar_link.STL"/>
      </geometry>
    </collision>
  </link>

  <joint name="lidar_joint" type="fixed">
    <origin xyz="0 0 0.0493" rpy="0 0 0"/>
    <parent link="base_link"/>
    <child link="lidar_link"/>
    <axis xyz="0 0 1"/>
  </joint>

  <link name="camera_link">
    <inertial>
      <origin xyz="-0.0077092572425532 2.63468590775279E-05 -0.00016251773378602" rpy="0 0 0"/>
      <mass value="0.00154849051596779"/>
      <inertia ixx="9.81439425205818E-08" ixy="1.55536718669128E-11" ixz="2.74799408025989E-09"
               iyy="6.15276310368582E-08" iyz="3.76651168163259E-10" izz="5.63302052123382E-08"/>
    </inertial>
    <visual>
      <origin xyz="0 0 0" rpy="0 0 0"/>
      <geometry>
        <mesh filename="package://omni_diff/meshes/boe_bot/camera_link.STL"/>
      </geometry>
      <material name="">
        <color rgba="0.792156862745098 0.819607843137255 0.933333333333333 1"/>
      </material>
    </visual>
    <collision>
      <origin xyz="0 0 0" rpy="0 0 0"/>
      <geometry>
        <mesh filename="package://omni_diff/meshes/boe_bot/camera_link.STL"/>
      </geometry>
    </collision>
  </link>

  <joint name="camera_joint" type="fixed">
    <origin xyz="0.0716965295130383 0 -0.00809859999999995" rpy="0 0 0"/>
    <parent link="base_link"/>
    <child link="camera_link"/>
    <axis xyz="0 0 0"/>
  </joint>

  <link name="imu_link">
    <inertial>
      <origin xyz="-1.73472347597681E-18 0.000180981912555563 0.000888343705367662" rpy="0 0 0"/>
      <mass value="0.000302850245192701"/>
      <inertia ixx="6.03209693376082E-09" ixy="-9.69699030246281E-25" ixz="-1.81322634255859E-27"
               iyy="9.48650699122206E-09" iyz="-8.97755442994359E-13" izz="1.54683861524513E-08"/>
    </inertial>
    <visual>
      <origin xyz="0 0 0" rpy="0 0 0"/>
      <geometry>
        <mesh filename="package://omni_diff/meshes/boe_bot/imu_link.STL"/>
      </geometry>
      <material name="">
        <color rgba="0.666666666666667 0.698039215686274 0.768627450980392 1"/>
      </material>
    </visual>
    <collision>
      <origin xyz="0 0 0" rpy="0 0 0"/>
      <geometry>
        <mesh filename="package://omni_diff/meshes/boe_bot/imu_link.STL"/>
      </geometry>
    </collision>
  </link>

  <joint name="imu_joint" type="fixed">
    <origin xyz="0 0 -0.0014" rpy="0 0 0"/>
    <parent link="base_link"/>
    <child link="imu_link"/>
    <axis xyz="0 0 0"/>
  </joint>

  <!-- LiDAR Plugin -->
  <gazebo reference="lidar_link">
    <material>Gazebo/FlatBlack</material>
    <sensor type="ray" name="head_rplidar_sensor">
      <pose>0 0 0 0 0 0</pose>
      <visualize>true</visualize>
      <update_rate>10.0</update_rate>
      <ray>
        <scan>
          <horizontal>
            <samples>720</samples>
            <resolution>1</resolution>
            <min_angle>-3.1415</min_angle>
            <max_angle>3.1415</max_angle>
          </horizontal>
        </scan>
        <range>
          <min>0.120</min>
          <max>10</max>
          <resolution>0.015</resolution>
        </range>
        <noise>
          <type>gaussian</type>
          <mean>0.0</mean>
          <stddev>0.01</stddev>
        </noise>
      </ray>
      <plugin name="gazebo_ros_head_rplidar_controller" filename="libgazebo_ros_laser.so">
        <topicName>/scan</topicName>
        <frameName>lidar_link</frameName>
        <gaussianNoise>0.01</gaussianNoise>
      </plugin>
    </sensor>
  </gazebo>

<!-- Depth Camera Plugin -->
<gazebo reference="camera_link">
  <sensor name="depth_camera_sensor" type="depth">
    <always_on>1</always_on>
    <update_rate>30</update_rate>
    <camera>
      <horizontal_fov>1.0472</horizontal_fov>
      <image>
        <width>640</width>
        <height>480</height>
        <format>R8G8B8</format>
      </image>
      <clip>
        <near>0.1</near>
        <far>100</far>
      </clip>
    </camera>
    <plugin name="depth_camera_plugin" filename="libgazebo_ros_depth_camera.so">
      <robotNamespace>/camera/depth</robotNamespace>
      <imageTopicName>image_raw</imageTopicName>
      <depthImageTopicName>depth/image_raw</depthImageTopicName>
      <pointCloudTopicName>depth/points</pointCloudTopicName>
      <cameraInfoTopicName>camera_info</cameraInfoTopicName>
      <frameName>camera_link</frameName>
    </plugin>
  </sensor>
</gazebo>

  <!-- IMU Plugin -->
  <gazebo reference="imu_link">
    <gravity>true</gravity>
    <sensor name="imu_sensor" type="imu">
      <always_on>true</always_on>
      <update_rate>100</update_rate>
      <visualize>true</visualize>
      <plugin name="imu_plugin" filename="libgazebo_ros_imu_sensor.so">
        <topicName>/imu</topicName>
        <bodyName>imu_link</bodyName>
        <updateRateHZ>10.0</updateRateHZ>
        <gaussianNoise>0.0</gaussianNoise>
        <xyzOffset>0 0 0</xyzOffset>
        <rpyOffset>0 0 0</rpyOffset>
        <frameName>imu_link</frameName>
        <initialOrientationAsReference>false</initialOrientationAsReference>
      </plugin>
      <pose>0 0 0 0 0 0</pose>
    </sensor>
  </gazebo>

  <!-- Differential Drive Plugin -->
  <gazebo>
    <plugin name="boe_bot_controller" filename="libgazebo_ros_diff_drive.so">
      <commandTopic>cmd_vel</commandTopic>
      <odometryTopic>odom</odometryTopic>
      <odometryFrame>odom</odometryFrame>
      <odometrySource>world</odometrySource>
      <publishOdomTF>true</publishOdomTF>
      <robotBaseFrame>base_footprint</robotBaseFrame>
      <publishWheelTF>false</publishWheelTF>
      <publishTf>true</publishTf>
      <publishWheelJointState>true</publishWheelJointState>
      <legacyMode>false</legacyMode>
      <updateRate>30</updateRate>
      <leftJoint>wheel_left_joint</leftJoint>
      <rightJoint>wheel_right_joint</rightJoint>
      <wheelSeparation>0.101</wheelSeparation>
      <wheelDiameter>0.066</wheelDiameter>
      <wheelAcceleration>1</wheelAcceleration>
      <wheelTorque>10</wheelTorque>
      <rosDebugLevel>debug</rosDebugLevel>
    </plugin>
  </gazebo>
</robot>